#VRML_SIM R2023b utf8

EXTERNPROTO "https://raw.githubusercontent.com/cyberbotics/webots/R2023b/projects/objects/backgrounds/protos/TexturedBackground.proto"
EXTERNPROTO "https://raw.githubusercontent.com/cyberbotics/webots/R2023b/projects/objects/backgrounds/protos/TexturedBackgroundLight.proto"
EXTERNPROTO "https://raw.githubusercontent.com/cyberbotics/webots/R2023b/projects/objects/floors/protos/RectangleArena.proto"
EXTERNPROTO "https://raw.githubusercontent.com/cyberbotics/webots/R2023b/projects/appearances/protos/OsbWood.proto"

WorldInfo {
}
Viewpoint {
  orientation 0.023045810908546963 0.08160885010934762 -0.996397955730238 0.5523441146742823
  position -1.3623087690557625 0.8482672853123497 0.42638265558664223
}
TexturedBackground {
}
TexturedBackgroundLight {
}
RectangleArena {
}
PointLight {
  attenuation 0 0 1
  location 0 0.6 0.01
}
DEF SLOPE Solid {
  translation 0 0 0.15
  rotation 0 1 0 -0.4
  children [
    Shape {
      appearance OsbWood {
      }
      geometry Box {
        size 0.7 0.15 0.025
      }
    }
  ]
}
Robot {
  children [
    Altimeter {
    }
    HingeJoint {
      jointParameters HingeJointParameters {
        position 16.7
        axis 0 1 0
        anchor 0 0 0.025
      }
      device [
        PositionSensor {
          name "left wheel sensor"
        }
        RotationalMotor {
          name "left wheel motor"
        }
      ]
      endPoint Solid {
        children [
          Pose {
            translation 0.06 0.05 0.215
            rotation 1 0 0 1.5708
            children [
              Shape {
                appearance PBRAppearance {
                  baseColor 1 0 0.0156863
                }
                geometry Cylinder {
                  height 0.01
                  radius 0.025
                }
              }
            ]
          }
        ]
        name "left wheel"
      }
    }
    HingeJoint {
      jointParameters HingeJointParameters {
        position 16.7
        axis 0 1 0
        anchor 0 0 0.025
      }
      device [
        PositionSensor {
          name "right wheel sensor"
        }
        RotationalMotor {
          name "left wheel motor"
        }
      ]
      endPoint Solid {
        translation 0 -0.1 0
        children [
          Pose {
            translation 0.06 0.05 0.215
            rotation 1 0 0 1.5708
            children [
              Shape {
                appearance PBRAppearance {
                  baseColor 1 0 0.0156863
                }
                geometry Cylinder {
                  height 0.01
                  radius 0.025
                }
              }
            ]
          }
        ]
        name "right wheel"
      }
    }
    Pose {
      translation 0.0577884 0 0.233078
      rotation 0 -1 0 0.4
      children [
        Shape {
          appearance PBRAppearance {
            baseColor 0.188235 0.160784 1
          }
          geometry Cylinder {
            height 0.08
            radius 0.05
          }
        }
      ]
    }
  ]
  name "MyBot"
}
